<mujoco model="centipede-top-g">
  <compiler angle="radian" coordinate="local" inertiafromgeom="true" settotalmass="14"/>
  <default>
    <joint armature=".1" damping=".01" limited="true" solimplimit="0 .8 .03" solreflimit=".02 1" stiffness="8"/>
    <geom conaffinity="0" condim="3" contype="1" friction=".4 .1 .1" rgba="0.8 0.6 .4 1" solimp="0.0 0.8 0.01" solref="0.02 1"/>
    <motor ctrllimited="true" ctrlrange="-1 1"/>
  </default>
  <size nstack="300000" nuser_geom="1"/>
  <option gravity="0 0 -9.81" timestep="0.01"/>
  <asset>
    <texture builtin="gradient" height="100" rgb1="1 1 1" rgb2="0 0 0" type="skybox" width="100"/>
    <texture builtin="flat" height="1278" mark="cross" markrgb="1 1 1" name="texgeom" random="0.01" rgb1="0.8 0.6 0.4" rgb2="0.8 0.6 0.4" type="cube" width="127"/>
    <texture builtin="checker" height="100" name="texplane" rgb1="0 0 0" rgb2="0.8 0.8 0.8" type="2d" width="100"/>
    <material name="MatPlane" reflectance="0.5" shininess="1" specular="1" texrepeat="60 60" texture="texplane"/>
    <material name="geom" texture="texgeom" texuniform="true"/>
  </asset>
  <worldbody>
    <light cutoff="100" diffuse="1 1 1" dir="-0 0 -1.3" directional="true" exponent="1" pos="0 0 1.3" specular=".1 .1 .1"/>
    <geom conaffinity="1" condim="3" material="MatPlane" name="floor" pos="0 0 0" rgba="0.8 0.9 0.8 1" size="40 40 40" type="plane"/>
    <body name="torso_0" pos="0 0 .7">
      <camera name="track" mode="trackcom" pos="0 -3 0.3" xyaxes="1 0 0 0 0 1"/>
      <joint armature="0" axis="1 0 0" damping="0" limited="false" name="root" pos="0 0 0" stiffness="0" type="free"/>
      <geom pos="0 0 0" name="torso_0" size="0.25" type="sphere" density="100"/>

      <body name="legbody_0" pos="0.0 -0.28 0">
        <joint axis="0 0 1" damping="4.5" name="lefthip_0" pos="0.0 0.0 0.0" range="-.698 .698" stiffness="180" type="hinge"/>
        <geom fromto="0.0 0.0 0.0 0.0 -0.28 0.0" name="legGeom_0" size="0.08" type="capsule" rgba=".08 .5 .3 1"/>
        <body pos="0 -0.28 0" name="frontFoot_0">
          <joint axis="1 0 0" damping="3" name="ankle_0" pos="0.0 0.0 0.0" range="0.524 1.75" stiffness="120" type="hinge"/>
          <geom fromto="0.0 0.0 0.0 0 -0.6 0.0" name="ankleGeom_0" size="0.08" type="capsule" rgba=".08 .5 .3 1"/>
        </body>
      </body>

      <body name="legbody_1" pos="0.0 0.28 0">
        <joint axis="0 0 1" damping="4.5" name="righthip_1" pos="0.0 0.0 0.0" range="-.698 .698" stiffness="180" type="hinge"/>
        <geom fromto="0.0 0.0 0.0 0.0 0.28 0.0" name="legGeom_1" size="0.08" type="capsule" rgba=".08 .5 .3 1"/>
        <body pos="0 0.28 0" name="frontFoot_1">
          <joint axis="-1 0 0" damping="3" name="ankle_1" pos="0.0 0.0 0.0" range="0.524 1.75" stiffness="120" type="hinge"/>
          <geom fromto="0.0 0.0 0.0 0 0.6 0.0" name="ankleGeom_1" size="0.08" type="capsule" rgba=".08 .5 .3 1"/>
        </body>
      </body>

      <body name="torso_1" pos="0.5 0 0">
        <geom name="torso_1" pos="0 0 0" size="0.25" type="sphere" density="100"/>
        <joint axis="0 0 1" name="body_1" pos="-0.25 0.0 0.0" range="-0.349 0.349" type="hinge"/>
        <joint axis="0 1 0" name="bodyupdown_1" pos="-0.25 0.0 0.0" range="-0.174 0.524" type="hinge"/>
        <body name="legbody_2" pos="0.0 -0.28 0">
        <joint axis="0 0 1" damping="4.5" name="lefthip_2" pos="0.0 0.0 0.0" range="-.698 .698" stiffness="180" type="hinge"/>
        <geom fromto="0.0 0.0 0.0 0.0 -0.28 0.0" name="legGeom_2" size="0.08" type="capsule" rgba=".08 .5 .3 1"/>
        <body pos="0 -0.28 0" name="frontFoot_2">
          <joint axis="1 0 0" damping="3" name="ankle_2" pos="0.0 0.0 0.0" range="0.524 1.75" stiffness="120" type="hinge"/>
          <geom fromto="0.0 0.0 0.0 0 -0.6 0.0" name="ankleGeom_2" size="0.08" type="capsule" rgba=".08 .5 .3 1"/>
        </body>
      </body>

        <body name="legbody_3" pos="0.0 0.28 0">
        <joint axis="0 0 1" damping="4.5" name="righthip_3" pos="0.0 0.0 0.0" range="-.698 .698" stiffness="180" type="hinge"/>
        <geom fromto="0.0 0.0 0.0 0.0 0.28 0.0" name="legGeom_3" size="0.08" type="capsule" rgba=".08 .5 .3 1"/>
        <body pos="0 0.28 0" name="frontFoot_3">
          <joint axis="-1 0 0" damping="3" name="ankle_3" pos="0.0 0.0 0.0" range="0.524 1.75" stiffness="120" type="hinge"/>
          <geom fromto="0.0 0.0 0.0 0 0.6 0.0" name="ankleGeom_3" size="0.08" type="capsule" rgba=".08 .5 .3 1"/>
        </body>
      </body>
      </body>


    </body>
  </worldbody>
  <actuator>
    <motor ctrllimited="true" ctrlrange="-1.0 1.0" joint="body_1" gear="100"/>
    <motor ctrllimited="true" ctrlrange="-1.0 1.0" joint="bodyupdown_1" gear="100"/>
    <motor ctrllimited="true" ctrlrange="-1.0 1.0" joint="lefthip_0" gear="150"/>
    <motor ctrllimited="true" ctrlrange="-1.0 1.0" joint="ankle_0" gear="150"/>
    <motor ctrllimited="true" ctrlrange="-1.0 1.0" joint="righthip_1" gear="150"/>
    <motor ctrllimited="true" ctrlrange="-1.0 1.0" joint="ankle_1" gear="150"/>
    <motor ctrllimited="true" ctrlrange="-1.0 1.0" joint="lefthip_2" gear="150"/>
    <motor ctrllimited="true" ctrlrange="-1.0 1.0" joint="ankle_2" gear="150"/>
    <motor ctrllimited="true" ctrlrange="-1.0 1.0" joint="righthip_3" gear="150"/>
    <motor ctrllimited="true" ctrlrange="-1.0 1.0" joint="ankle_3" gear="150"/>
  </actuator>
</mujoco>