<mujoco model="cheetah">
  <compiler angle="radian" coordinate="local" inertiafromgeom="true" settotalmass="14"/>
  <default>
    <joint armature=".1" damping=".01" limited="true" solimplimit="0 .8 .03" solreflimit=".02 1" stiffness="8"/>
    <geom conaffinity="0" condim="3" contype="1" friction=".4 .1 .1" rgba="0.8 0.6 .4 1" solimp="0.0 0.8 0.01" solref="0.02 1"/>
    <motor ctrllimited="true" ctrlrange="-1 1"/>
  </default>
  <size nstack="300000" nuser_geom="1"/>
  <option gravity="0 0 -9.81" timestep="0.01"/>
  <asset>
    <texture builtin="gradient" height="100" rgb1="1 1 1" rgb2="0 0 0" type="skybox" width="100"/>
    <texture builtin="flat" height="1278" mark="cross" markrgb="1 1 1" name="texgeom" random="0.01" rgb1="0.8 0.6 0.4" rgb2="0.8 0.6 0.4" type="cube" width="127"/>
    <texture builtin="checker" height="100" name="texplane" rgb1="0 0 0" rgb2="0.8 0.8 0.8" type="2d" width="100"/>
    <material name="MatPlane" reflectance="0.5" shininess="1" specular="1" texrepeat="60 60" texture="texplane"/>
    <material name="geom" texture="texgeom" texuniform="true"/>
  </asset>
  <worldbody>
    <light cutoff="100" diffuse="1 1 1" dir="-0 0 -1.3" directional="true" exponent="1" pos="0 0 1.3" specular=".1 .1 .1"/>
    <geom conaffinity="1" condim="3" material="MatPlane" name="floor" pos="0 0 0" rgba="0.8 0.9 0.8 1" size="40 40 40" type="plane"/>
    <body name="torso" pos="0 0 .7">
      <camera name="track" mode="trackcom" pos="0 -3 0.3" xyaxes="1 0 0 0 0 1"/>
      <joint armature="0" axis="1 0 0" damping="0" limited="false" name="rootx" pos="0 0 0" stiffness="0" type="slide"/>
      <joint armature="0" axis="0 0 1" damping="0" limited="false" name="rootz" pos="0 0 0" stiffness="0" type="slide"/>
      <joint armature="0" axis="0 1 0" damping="0" limited="false" name="rooty" pos="0 0 0" stiffness="0" type="hinge"/>
      <geom fromto="-.5 0 0 .5 0 0" name="torso" size="0.08" type="ellipsoid"/>
      <geom axisangle="0 1 0 .87" name="head" pos=".6 0 .1" size="0.046 .15" type="capsule"/>
      <!-- <site name='tip'  pos='.15 0 .11'/>-->
      <body name="left_bthigh" pos="-.4 0.07 0">
        <joint axis="0 1 0" damping="6" name="left_bthigh" pos="0 0 0" range="-.52 1.05" stiffness="240" type="hinge"/>
        <geom axisangle="0 1 0 -3.8" name="left_bthigh" pos=".1 0 -.13" size="0.046 .145" type="capsule"/>
        <body name="left_bshin" pos=".16 0 -.25">
          <joint axis="0 1 0" damping="4.5" name="left_bshin" pos="0 0 0" range="-.785 .785" stiffness="180" type="hinge"/>
          <geom axisangle="0 1 0 -2.03" name="left_bshin" pos="-.14 0 -.07" rgba="0.9 0.6 0.6 1" size="0.046 .15" type="capsule"/>
          <body name="left_bfoot" pos="-.28 0 -.14">
            <joint axis="0 1 0" damping="3" name="left_bfoot" pos="0 0 0" range="-.4 .785" stiffness="120" type="hinge"/>
            <geom axisangle="0 1 0 -.27" name="left_bfoot" pos=".03 0 -.097" rgba="0.9 0.6 0.6 1" size="0.046 .094" type="capsule"/>
          </body>
        </body>
      </body>
       <body name="right_bthigh" pos="-.4 -0.07 0">
        <joint axis="0 1 0" damping="6" name="right_bthigh" pos="0 0 0" range="-.52 1.05" stiffness="240" type="hinge"/>
        <geom axisangle="0 1 0 -3.8" name="right_bthigh" pos=".1 0 -.13" size="0.046 .145" type="capsule"/>
        <body name="right_bshin" pos=".16 0 -.25">
          <joint axis="0 1 0" damping="4.5" name="right_bshin" pos="0 0 0" range="-.785 .785" stiffness="180" type="hinge"/>
          <geom axisangle="0 1 0 -2.03" name="right_bshin" pos="-.14 0 -.07" rgba="0.9 0.6 0.6 1" size="0.046 .15" type="capsule"/>
          <body name="right_bfoot" pos="-.28 0 -.14">
            <joint axis="0 1 0" damping="3" name="right_bfoot" pos="0 0 0" range="-.4 .785" stiffness="120" type="hinge"/>
            <geom axisangle="0 1 0 -.27" name="right_bfoot" pos=".03 0 -.097" rgba="0.9 0.6 0.6 1" size="0.046 .094" type="capsule"/>
          </body>
        </body>
      </body>
      <body name="left_fthigh" pos=".4 0.07 0">
        <joint axis="0 1 0" damping="4.5" name="left_fthigh" pos="0 0 0" range="-1 .7" stiffness="180" type="hinge"/>
        <geom axisangle="0 1 0 .52" name="left_fthigh" pos="-.07 0 -.12" size="0.046 .133" type="capsule"/>
        <body name="left_fshin" pos="-.14 0 -.24">
          <joint axis="0 1 0" damping="3" name="left_fshin" pos="0 0 0" range="-1.2 .87" stiffness="120" type="hinge"/>
          <geom axisangle="0 1 0 -.6" name="left_fshin" pos=".065 0 -.09" rgba="0.9 0.6 0.6 1" size="0.046 .106" type="capsule"/>
          <body name="left_ffoot" pos=".13 0 -.18">
            <joint axis="0 1 0" damping="1.5" name="left_ffoot" pos="0 0 0" range="-.5 .5" stiffness="60" type="hinge"/>
            <geom axisangle="0 1 0 -.6" name="left_ffoot" pos=".045 0 -.07" rgba="0.9 0.6 0.6 1" size="0.046 .07" type="capsule"/>
          </body>
        </body>
      </body>
      <body name="right_fthigh" pos=".4 -0.07 0">
        <joint axis="0 1 0" damping="4.5" name="right_fthigh" pos="0 0 0" range="-1 .7" stiffness="180" type="hinge"/>
        <geom axisangle="0 1 0 .52" name="right_fthigh" pos="-.07 0 -.12" size="0.046 .133" type="capsule"/>
        <body name="right_fshin" pos="-.14 0 -.24">
          <joint axis="0 1 0" damping="3" name="right_fshin" pos="0 0 0" range="-1.2 .87" stiffness="120" type="hinge"/>
          <geom axisangle="0 1 0 -.6" name="right_fshin" pos=".065 0 -.09" rgba="0.9 0.6 0.6 1" size="0.046 .106" type="capsule"/>
          <body name="right_ffoot" pos=".13 0 -.18">
            <joint axis="0 1 0" damping="1.5" name="right_ffoot" pos="0 0 0" range="-.5 .5" stiffness="60" type="hinge"/>
            <geom axisangle="0 1 0 -.6" name="right_ffoot" pos=".045 0 -.07" rgba="0.9 0.6 0.6 1" size="0.046 .07" type="capsule"/>
          </body>
        </body>
      </body>
    </body>
  </worldbody>
  <actuator>
    <motor gear="120" joint="left_bthigh" name="left_bthigh"/>
    <motor gear="90" joint="left_bshin" name="left_bshin"/>
    <motor gear="60" joint="left_bfoot" name="left_bfoot"/>
    <motor gear="120" joint="left_fthigh" name="left_fthigh"/>
    <motor gear="60" joint="left_fshin" name="left_fshin"/>
    <motor gear="30" joint="left_ffoot" name="left_ffoot"/>
    <motor gear="120" joint="right_bthigh" name="right_bthigh"/>
    <motor gear="90" joint="right_bshin" name="right_bshin"/>
    <motor gear="60" joint="right_bfoot" name="right_bfoot"/>
    <motor gear="120" joint="right_fthigh" name="right_fthigh"/>
    <motor gear="60" joint="right_fshin" name="right_fshin"/>
    <motor gear="30" joint="right_ffoot" name="right_ffoot"/>
  </actuator>
</mujoco>