<mujoco model="2-link 6-muscle leg">
  <option timestep="0.005" iterations="50" solver="Newton" tolerance="1e-10"/>

  <visual>
    <rgba haze=".3 .3 .3 1"/>
  </visual>

  <default>
    <joint type="hinge" pos="0 0 0" axis="0 1 0" limited="true" range="0 120" damping="0.1"/>
    <muscle ctrllimited="true" ctrlrange="0 1"/>
  </default>

  <asset>
    <texture type="skybox" builtin="gradient" rgb1="0.6 0.6 0.6" rgb2="0 0 0" width="512" height="512"/>

    <texture name="texplane" type="2d" builtin="checker" rgb1=".25 .25 .25" rgb2=".3 .3 .3" width="512" height="512" mark="cross" markrgb=".8 .8 .8"/>

    <material name="matplane" reflectance="0.3" texture="texplane" texrepeat="1 1" texuniform="true"/>
  </asset>

  <worldbody>
    <geom name="floor" pos="0 0 -1" size="0 0 1" type="plane" material="matplane"/>

    <light directional="true" diffuse=".8 .8 .8" specular=".2 .2 .2" pos="0 0 5" dir="0 0 -1"/>

    <site name="s0" pos="0 0 0.15" size="0.02"/>
    <site name="x0" pos="0.15 0 0" size="0.02" rgba="0 .7 0 1" group="1"/>

    <body pos="0 0 0">
      <geom name="upper leg" type="capsule" size="0.045" fromto="0 0 0  0 0 -0.5" rgba=".5 .1 .1 1"/>
      <joint name="hip"/>
      <geom name="hip" type="cylinder" pos="0 0 0" size=".1 .05" rgba=".5 .1 .8 .5" mass="0" group="1" euler="90 0 0"/>

      <site name="s1" pos="0.10 0 0.06" size="0.02"/>
      <site name="s2" pos="-0.10 0 0.06" size="0.02"/>
      <site name="s3" pos="0.06 0 -0.4" size="0.02"/>
      <site name="s4" pos="-0.06 0 -0.4" size="0.02"/>
      <site name="s5" pos="0.1 0 -0.25" size="0.02"/>
      <site name="s6" pos="-0.1 0 -0.25" size="0.02"/>
      <site name="x1" pos="0.15 0 -0.5" size="0.02" rgba="0 .7 0 1" group="1"/>

      <body pos="0 0 -0.5">
        <geom name="lower leg" type="capsule" size="0.035" fromto="0 0 0  0 0 -0.5" rgba=".5 .1 .1 1"/>
        <joint name="knee"/>
        <geom name="knee" type="cylinder" pos="0 0 0" size=".08 .05" rgba=".5 .1 .8 .5" mass="0" group="1" euler="90 0 0"/>

        <site name="s7" pos="0.05 0 -0.11" size="0.02"/>
        <site name="s8" pos="-0.05 0 -0.11" size="0.02"/>
        <site name="s9" pos="0.05 0 -0.4" size="0.02"/>
        <site name="s10" pos="-0.05 0 -0.4" size="0.02"/>
        <site name="s11" pos="0.09 0 -0.25" size="0.02"/>
        <site name="s12" pos="-0.09 0 -0.25" size="0.02"/>
        <body pos="0 0 -0.5">
          <geom name="foot" type="capsule" size="0.035" fromto="0 0 0  0.1 0 0" rgba=".5 .1 .1 1"/>
          <joint name="ankle"/>
          <geom name="ankle" type="cylinder" pos="0 0 0" size=".06 .03" rgba=".5 .1 .8 .5" mass="0" group="1" euler="90 0 0"/>
        </body> 
      </body>
    </body>
  </worldbody>

  <tendon>
    <spatial name="SF" width="0.01">
      <site site="s0"/>
      <geom geom="hip" sidesite="x0"/>
      <site site="s1"/>
    </spatial>

    <spatial name="SE" width="0.01">
      <site site="s0"/>
      <geom geom="hip" />
      <site site="s2"/>
    </spatial>

    <spatial name="EF" width="0.01">
      <site site="s3"/>
      <geom geom="knee" sidesite="x1"/>
      <site site="s7"/>
    </spatial>

    <spatial name="EE" width="0.01">
      <site site="s4"/>
      <geom geom="knee" />
      <site site="s8"/>
    </spatial>

    <spatial name="BF" width="0.009" rgba=".4 .6 .4 1">
      <site site="s0"/>
      <geom geom="hip" sidesite="x0"/>
      <site site="s5"/>
      <geom geom="knee" sidesite="x1"/>
      <site site="s7"/>
    </spatial>

    <spatial name="BE" width="0.009" rgba=".4 .6 .4 1">
      <site site="s0"/>
      <geom geom="hip" />
      <site site="s6"/>
      <geom geom="knee"/>
      <site site="s8"/>
    </spatial>

   <spatial name="AF" width="0.009" rgba=".4 .6 .4 1">
      <site site="s3"/>
      <geom geom="knee" sidesite="x1"/>
      <site site="s11"/>
      <geom geom="ankle" sidesite="x1"/>
      <site site="s9"/>
    </spatial>

    <spatial name="AE" width="0.009" rgba=".4 .6 .4 1">
      <site site="s4"/>
      <geom geom="knee" />
      <site site="s12"/>
      <geom geom="ankle" />
      <site site="s10"/>
    </spatial>

  </tendon>

  <actuator>
   <muscle name="SF" tendon="SF"/>
   <muscle name="SE" tendon="SE"/>
   <muscle name="EF" tendon="EF"/>
   <muscle name="EE" tendon="EE"/>
   <muscle name="BF" tendon="BF"/>
   <muscle name="BE" tendon="BE"/>
   <muscle name="AF" tendon="AF"/>
  </actuator>
</mujoco>